<?xml version="1.0"?>

<robot name="pharos1"
    xmlns:sensor="http://playerstage.sourceforge.net/gazebo/xmlschema/#sensor"
    xmlns:controller="http://playerstage.sourceforge.net/gazebo/xmlschema/#controller"
    xmlns:interface="http://playerstage.sourceforge.net/gazebo/xmlschema/#interface">
    
  <material name="Green">
    <color rgba="0.0 0.8 0.0 1.0"/>
  </material>

  <property name="M_PI" value="3.14159"/>
  <property name="SCALE" value="0.0254"/>
  <property name="base_x" value="0.33" />
  <property name="base_y" value="0.33" />

  <!-- base_footprint is a fictitious link(frame) that is on the ground right below base_link origin, navigation stack depends on this frame -->

  <link name="base_footprint">
    <inertial>
      <mass value="0.0001" />
      <origin xyz="0 0 0" />
      <inertia ixx="0.0001" ixy="0.0" ixz="0.0"
              iyy="0.0001" iyz="0.0" 
              izz="0.0001" />
    </inertial>

    <visual>
      <origin xyz="0 0 0" rpy="0 0 0" />
      <geometry>
        <box size="0.001 0.001 0.001" />
      </geometry>
      <material name="Green" />
    </visual>

    <collision>
      <origin xyz="0 0 0.017" rpy="0 0 0" />
      <geometry>
       <box size="0.001 0.001 0.001" />
      </geometry>
    </collision>
  </link>

  <link name="base_link">
    <inertial>
      <mass value="1" />
      <origin xyz="0 0 0.0308" />
      <inertia ixx="1.0" ixy="0.0" ixz="0.0"
        iyy="1.0" iyz="0.0" izz="1.0" />
    </inertial>

    <visual>
      <origin xyz=" 0 0 0.0308" rpy="0 0 0" />
      <geometry>
        <mesh filename="package://turtlebot_description/meshes/create_body.dae"/>
      </geometry>
    </visual>

    <collision>
      <origin xyz="0.0 0.0 0.0308" rpy="0 0 0" />
      <geometry>
        <cylinder length="0.0611632" radius="0.16495"/>
      </geometry>
    </collision>
  </link>

  <link name="wall_sensor_link">
    <inertial>
      <mass value="0.01" />
      <origin xyz="0 0 0"/>
      <inertia ixx="1.0" ixy="0.0" ixz="0.0"
        iyy="1.0" iyz="0.0" izz="1.0" />
    </inertial>
  </link>


  <link name="left_cliff_sensor_link">
    <inertial>
      <mass value="0.01" />
      <origin xyz="0 0 0"/>
      <inertia ixx="1.0" ixy="0.0" ixz="0.0"
        iyy="1.0" iyz="0.0" izz="1.0" />
    </inertial>
  </link>

  <link name="right_cliff_sensor_link">
    <inertial>
      <mass value="0.01" />
      <origin xyz="0 0 0"/>
      <inertia ixx="1.0" ixy="0.0" ixz="0.0"
        iyy="1.0" iyz="0.0" izz="1.0" />
    </inertial>
  </link>

  <link name="leftfront_cliff_sensor_link">
    <inertial>
      <mass value="0.01" />
      <origin xyz="0 0 0"/>
      <inertia ixx="1.0" ixy="0.0" ixz="0.0"
        iyy="1.0" iyz="0.0" izz="1.0" />
    </inertial>
  </link>

  <link name="rightfront_cliff_sensor_link">
    <inertial>
      <mass value="0.01" />
      <origin xyz="0 0 0"/>
      <inertia ixx="1.0" ixy="0.0" ixz="0.0"
        iyy="1.0" iyz="0.0" izz="1.0" />
    </inertial>
  </link>


  <joint name="base_footprint_joint" type="fixed">
    <origin xyz="0 0 0.017" rpy="0 0 0" />        
    <parent link="base_footprint"/>
    <child link="base_link" />
  </joint>

  <joint name="base_wall_sensor_joint" type="fixed">
    <origin xyz="0.09 -0.120 0.042" rpy="0 0 -1.0" />        
    <parent link="base_link"/>
    <child link="wall_sensor_link" />
  </joint>

  <joint name="base_left_cliff_sensor_joint" type="fixed">
    <origin xyz="0.07 0.14 0.01" rpy="0 1.57079 0" />        
    <parent link="base_link"/>
    <child link="left_cliff_sensor_link" />
  </joint>

  <joint name="base_right_cliff_sensor_joint" type="fixed">
    <origin xyz="0.07 -0.14 0.01" rpy="0 1.57079 0" />        
    <parent link="base_link"/>
    <child link="right_cliff_sensor_link" />
  </joint>

  <joint name="base_leftfront_cliff_sensor_joint" type="fixed">
    <origin xyz="0.15 0.04 0.01" rpy="0 1.57079 0" />        
    <parent link="base_link"/>
    <child link="leftfront_cliff_sensor_link" />
  </joint>

  <joint name="base_rightfront_cliff_sensor_joint" type="fixed">
    <origin xyz="0.15 -0.04 0.01" rpy="0 1.57079 0" />        
    <parent link="base_link"/>
    <child link="rightfront_cliff_sensor_link" />
  </joint>

  <link name="left_wheel_link">
    <inertial>
      <origin xyz="0 0 0"/>
      <mass value="0.01" />
      <inertia ixx="1.0" ixy="0.0" ixz="0.0"
        iyy="1.0" iyz="0.0" izz="1.0" />
    </inertial>

    <visual>
      <origin xyz="0 0 0" rpy="0 1.5707 1.5707" />
      <geometry>
        <cylinder radius="0.033" length = "0.023"/>
      </geometry>
    </visual>

    <collision>
      <origin xyz="0 0 0" rpy="0 1.5707 1.5707" />
      <geometry>
        <cylinder radius="0.033" length = "0.023"/>
      </geometry>
    </collision>
  </link>

  <joint name="left_wheel_joint" type="continuous">
    <origin xyz="0 0.13 0.015" rpy="0 0 0"/>
    <parent link="base_link"/>
    <child link="left_wheel_link"/>
    <axis xyz="0 1 0"/>
  </joint>

  <link name="right_wheel_link">
    <inertial>
      <origin xyz="0 0 0"/>
      <mass value="0.01" />
      <inertia ixx="1.0" ixy="0.0" ixz="0.0"
        iyy="1.0" iyz="0.0" izz="1.0" />
    </inertial>

    <visual>
      <origin xyz="0 0 0" rpy="0 1.5707 1.5707" />
      <geometry>
        <cylinder radius="0.033" length = "0.023"/>
      </geometry>
    </visual>

    <collision>
      <origin xyz="0 0 0" rpy="0 1.5707 1.5707" />
      <geometry>
        <cylinder radius="0.033" length = "0.023"/>
      </geometry>
    </collision>
  </link>

  <joint name="right_wheel_joint" type="continuous">
    <origin xyz="0 -0.13 0.015" rpy="0 0 0"/>
    <parent link="base_link"/>
    <child link="right_wheel_link"/>
    <axis xyz="0 1 0"/>
  </joint>

  <link name="rear_wheel_link">
    <inertial>
      <origin xyz="0 0 0"/>
      <mass value="0.001" />
      <inertia ixx="1.0" ixy="0.0" ixz="0.0"
        iyy="1.0" iyz="0.0" izz="1.0" />
    </inertial>

    <visual>
      <origin xyz="0 0 0" rpy="0 1.5707 1.5707"/>
      <geometry>
        <sphere radius="0.018" />
      </geometry>
    </visual>

    <collision>
      <origin xyz="0 0 0" rpy="0 1.5707 1.5707" />
      <geometry>
        <sphere radius="0.018" />
      </geometry>
    </collision>
  </link>
  <joint name="rear_castor_joint" type="fixed">
    <origin xyz="-0.13 0 0.0" rpy="0 0 0"/>
    <parent link="base_link"/>
    <child link="rear_wheel_link"/>
    <axis xyz="0 1 0"/>
  </joint>

  <link name="front_wheel_link">
    <inertial>
      <origin xyz="0 0 0" />
      <mass value="0.01" />
      <inertia ixx="1.0" ixy="0.0" ixz="0.0"
        iyy="1.0" iyz="0.0" izz="1.0" />
    </inertial>

    <visual>
      <origin xyz="0 0 0" rpy="0 1.5707 1.5707"/>
      <geometry>
        <sphere radius="0.018" />
      </geometry>
    </visual>

    <collision>
      <origin xyz="0 0 0" rpy="0 1.5707 1.5707" />
      <geometry>
        <sphere radius="0.018" />
      </geometry>
    </collision>
  </link>

  <joint name="front_castor_joint" type="continuous">
    <origin xyz="0.13 0 0.0" rpy="0 0 0"/>
    <parent link="base_link"/>
    <child link="front_wheel_link"/>
    <axis xyz="0 1 0"/>
  </joint>

  <joint name="gyro_joint" type="fixed">
    <origin xyz="0 0 0.04" rpy="0 0 0" />
    <parent link="base_link" />
    <child link="gyro_link" />
  </joint>

  <link name="gyro_link">
    <visual>
      <geometry>
        <box size="0.02 0.035 0.002" />
      </geometry>
      <material name="Green" />
    </visual>
    <inertial>
      <mass value="0.000001" />
      <origin xyz="0 0 0" />
      <inertia ixx="0.0001" ixy="0.0" ixz="0.0"
        iyy="0.0001" iyz="0.0"
        izz="0.0001" />
    </inertial>
  </link>

  <joint name="base_marker_joint" type="fixed">
    <origin xyz="0.093 0 0.123" rpy="0 0 0" />
    <parent link="base_link" />
    <child link="marker_link" />
  </joint>

  <link name="marker_link">
    <visual>
      <geometry>
        <box size="0.228 0.228 0.002" />
      </geometry>
      <material name="Green" />
    </visual>
    <inertial>
      <mass value="0.000001" />
      <origin xyz="0 0 0" />
      <inertia ixx="0.0001" ixy="0.0" ixz="0.0"
        iyy="0.0001" iyz="0.0"
        izz="0.0001" />
    </inertial>
  </link>

  <joint name="base_kinect_joint" type="fixed">
    <origin xyz="-0.127 0 0.233" rpy="0 0 0" />
    <parent link="base_link" />
    <child link="kinect_link" />
  </joint>

  <link name="kinect_link">
    <inertial>
      <mass value="0.00001" />
      <origin xyz="0 0 0" />
      <inertia ixx="1.0" ixy="0.0" ixz="0.0"
        iyy="1.0" iyz="0.0"
        izz="1.0" />
    </inertial>

    <visual>
      <origin xyz=" 0 0 0 " rpy="0 0 0" />
      <geometry>
        <mesh filename="package://turtlebot_description/meshes/kinect.dae"/>
      </geometry>
    </visual>

    <collision>
      <origin xyz="0.0 0.0 0.0" rpy="0 0 0" />
      <geometry>
        <box size="0.0730 .2760 0.0720"/>
      </geometry>
    </collision>

  </link>

  <joint name="kinect_depth_joint" type="fixed">
    <origin xyz="0 0.018 0" rpy="0 0 0" />
    <parent link="kinect_link" />
    <child link="kinect_depth_frame" />
  </joint>

  <link name="kinect_depth_frame">
    <inertial>
      <mass value="0.000001" />
      <origin xyz="0 0 0" />
      <inertia ixx="0.0001" ixy="0.0" ixz="0.0"
        iyy="0.0001" iyz="0.0"
        izz="0.0001" />
    </inertial>
  </link>

  <joint name="kinect_depth_optical_joint" type="fixed">
    <origin xyz="0 0 0" rpy="${-M_PI/2} 0 ${-M_PI/2}" />
    <parent link="kinect_depth_frame" />
    <child link="kinect_depth_optical_frame" />
  </joint>

  <link name="kinect_depth_optical_frame">
    <inertial>
      <mass value="0.000001" />
      <origin xyz="0 0 0" />
      <inertia ixx="0.0001" ixy="0.0" ixz="0.0"
        iyy="0.0001" iyz="0.0"
        izz="0.0001" />
    </inertial>
  </link>


  <joint name="kinect_rgb_joint" type="fixed">
    <origin xyz="0 -0.005 0" rpy="0 0 0" />
    <parent link="kinect_link" />
    <child link="kinect_rgb_frame" />
  </joint>

  <link name="kinect_rgb_frame">
    <inertial>
      <mass value="0.000001" />
      <origin xyz="0 0 0" />
      <inertia ixx="0.0001" ixy="0.0" ixz="0.0"
        iyy="0.0001" iyz="0.0"
        izz="0.0001" />
    </inertial>
  </link>


  <joint name="kinect_rgb_optical_joint" type="fixed">
    <origin xyz="0 0 0" rpy="${-M_PI/2} 0 ${-M_PI/2}" />
    <parent link="kinect_rgb_frame" />
    <child link="kinect_rgb_optical_frame" />
  </joint>

  <link name="kinect_rgb_optical_frame">
    <inertial>
      <mass value="0.000001" />
      <origin xyz="0 0 0" />
      <inertia ixx="0.0001" ixy="0.0" ixz="0.0"
        iyy="0.0001" iyz="0.0"
        izz="0.0001" />
    </inertial>
  </link>

</robot>
